Workbook

Sheet 00说明
B1: 《供水营销管理系统》项目度量与需求分析工作簿 — 使用说明
B3: 一、工作簿用途
B4: 本工作簿汇集《供水营销管理系统》需求规格说明书（SRS）的功能分解与质量检查结果，以及两个已结项软件项目的度量数据，用于：①跨项目度量对比与组织级基线参考；②按可调阈值的红绿灯偏差监控；③新项目（24个二级功能）估算与需求评审支撑。
B6: 二、工作表清单
B7: 「01参数」 监控阈值与口径参数（全部蓝字可修改），缺陷加权权重、人时换算也在此维护，供全簿公式引用
B8: 「02项目1度量」 项目1（度量表1，256FP，2025-02-24~06-30）：规模/工作量/进度/成本四块 + 关键派生指标（供04/05引用）
B9: 「03项目2度量」 项目2（度量表2，KSSH-1102，327FP，2024-09-13~2025-04-02）：工作量/规模效率/工期/成本/缺陷/评审 + 关键派生指标
B10: 「04汇总对比」 两项目15项指标横向对比，全部跨表引用公式取数，附差异说明
B11: 「05监控报告」 红绿灯仪表盘：11项指标 × 01参数阈值自动判定（●正常/▲预警/✖超限），底部自动生成结论与风险建议
B12: 「06功能分解」 SRS功能分解WBS全清单（8模块27功能，含3个银行代收接口），含优先级映射、输入输出、验收要点；下方附范围缺口扩展建议
B13: 「07质量检查」 SRS质量问题清单41项（高18/中16/低7），按严重度与类别自动统计，支持筛选
B15: 三、使用方法
... B48: 14. P2工期总计行的「计划总工期/实际总工期」单元格为表头文字无数值，总工期121/130天取自累计列，总计行偏差率取交付验收阶段累计值

Sheet 01参数
A1: 监控阈值参数（本表蓝字均可修改，修改后 02/03/05 各表自动联动）
A2: 蓝字=输入；其余表通过 ='01参数'!$C$n 引用本表。
A3: 参数名称 | B3: 符号 | C3: 数值 | D3: 判定方向/口径 | E3: 默认值 | F3: 说明
A4: 工作量偏差控制范围 | B4: thr_effort | C4: 0.15 | D4: |偏差率|≤阈值 | E4: ±15% | F4: 实际总工作量相对估计值的允许偏差
A5: 工期(进度)偏差控制范围 | B5: thr_schedule | C5: 0.15 | D5: |偏差率|≤阈值 | E5: ±15% | F5: 进度/累计工期偏差率允许范围
A6: 成本偏差控制范围 | B6: thr_cost | C6: 0.15 | D6: |偏差率|≤阈值 | E6: ±15% | F6: 成本偏差率允许范围
A7: 规模偏差控制范围 | B7: thr_size | C7: 0.1 | D7: |偏差率|≤阈值 | E7: ±10% | F7: 功能点规模偏差率允许范围
A8: 缺陷探测率目标 | B8: thr_detect | C8: 0.75 | D8: 指标≥目标 | E8: ≥75% | F8: 系统测试加权缺陷占总加权缺陷比例的下限
A9: 功能点耗时率目标(人时/FP) | B9: thr_hourfp | C9: 7.15 | D9: 指标≤目标 | E9: ≤7.15 | F9: 每功能点耗用人时上限
A10: 评审效率目标(个/人时) | B10: thr_review | C10: 0.75 | D10: 指标≥目标 | E10: ≥0.75 | F10: 评审每人时发现缺陷数下限
A11: 红绿灯规则系数 | B11: coef_green | C11: 0.6 | D11: 绿区=阈值×系数 | E11: 0.6 | F11: |偏差|≤阈值×系数为●正常；≤阈值为▲预警；>阈值为✖超限
A13: 缺陷加权权重（由项目2缺陷表原始数据反推核对：集成102/验收28/总计130全部吻合；非常见10/5/2/1口径）
A14: 致命缺陷权重 | B14: w_fatal | C14: 8 | F14: 缺陷加权数=Σ(各级数量×权重)
A15: 严重缺陷权重 | B15: w_severe | C15: 4 | F15: 缺陷加权数=Σ(各级数量×权重)
A16: 一般缺陷权重 | B16: w_normal | C16: 1 | F16: 缺陷加权数=Σ(各级数量×权重)
A17: 细微缺陷权重 | B17: w_minor | C17: 0.5 | F17: 缺陷加权数=Σ(各级数量×权重)
A19: 单位换算：1人天 = | B19: hours_per_day | C19: 8 | D19: 人时 | F19: 功能点耗时率换算用；1人月=20人天
A21: 红绿灯判定规则
A22: 红黄绿判定规则：|偏差率|≤阈值×0.6 为绿色（正常），阈值×0.6<|偏差率|≤阈值 为黄色（预警），|偏差率|>阈值 为红色（超限）。工作量/进度/成本偏差阈值±15%（绿区≤9%）、规模偏差阈值±10%（绿区≤6%）；达标线类指标：缺陷探测率≥75%、评审效率≥0.75个/人时、功能点耗时率≤7.15人时/FP，达标为绿、未达标为红。

Sheet 02项目1度量
A1: 项目1度量数据（度量表1） 周期：2025-02-24 ~ 2025-06-30 实际规模256FP
A2: 蓝字=原表计划/实际原值（可修改）；黑字=公式；总计行与偏差率一律公式计算。
A4: 一、规模度量（各阶段规模对比，单位：功能点FP）
A5: 编号 | B5: 阶段 | C5: 估算规模(FP) | D5: 实际规模(FP) | E5: 规模偏差率 | F5: 说明
A6: 1 | B6: 项目策划 | C6: 176 | D6: 176 | E6: =IF($C6="","",($D6-$C6)/$C6) -> 0
A7: 2 | B7: 需求 | C7: 176 | D7: 185 | E7: =IF($C7="","",($D7-$C7)/$C7) -> 0.051136364
A8: 3 | B8: 设计 | C8: 185 | D8: 185 | E8: =IF($C8="","",($D8-$C8)/$C8) -> 0
A9: 4 | B9: 实现 | C9: 186 | D9: 186 | E9: =IF($C9="","",($D9-$C9)/$C9) -> 0
A10: 5 | B10: 测试 | C10: 187 | D10: 187 | E10: =IF($C10="","",($D10-$C10)/$C10) -> 0
A11: 6 | B11: 验收结项 | D11: 256 | E11: =IF($C11="","",($D11-$C11)/$C11) | F11: 验收结项无估算值，偏差率空缺（估算187FP→实际256FP，跳变约27%）
A12: 结论（原表）：项目规模的估算在不同阶段有些偏差，在项目策划阶段估算规模为176功能，需求阶段为185个功能。策划阶段比需求阶段少9个功能点，说明对需求分析得不够全面，所以一方面要加强对客户的沟通，另一方面要改进需求调研方法。
A14: 二、工作量度量（单位：人天；1人月=20人天，1人天=8人时；偏差率以需求阶段估计值为基准）
A15: 编号 | B15: 工作量分类 | C15: 活动/阶段 | D15: 估计值-策划阶段 | E15: 估计值-需求阶段 | F15: 实际值 | G15: 工作量偏差率
A16: 1 | B16: 软件工程活动 | C16: 需求 | D16: 47.637333 | E16: 50.073333 | F16: 47.478431 | G16: =($F16-$E16)/$E16 -> -0.051822034
A17: 2 | B17: 软件工程活动 | C17: 设计 | D17: 22.997333 | E17: 24.173333 | F17: 22.913725 | G17: =($F17-$E17)/$E17 -> -0.052107329
A18: 3 | B18: 软件工程活动 | C18: 编码 | D18: 47.637333 | E18: 50.073333 | F18: 48.21 | G18: =($F18-$E18)/$E18 -> -0.037212089
A19: 4 | B19: 软件工程活动 | C19: 测试 | D19: 34.496 | E19: 36.26 | F19: 33.12 | G19: =($F19-$E19)/$E19 -> -0.086596801
A20: 5 | B20: 软件工程活动 | C20: 验收 | D20: 11.498667 | E20: 12.086667 | F20: 10.53 | G20: =($F20-$E20)/$E20 -> -0.12879206
A21: 6 | B21: 项目策划 | C21: 全阶段 | D21: 14.08 | E21: 14.8 | F21: 14.33 | G21: =($F21-$E21)/$E21 -> -0.031756757
A22: 7 | B22: 项目监控 | C22: 全阶段 | D22: 16.896 | E22: 17.76 | F22: 18.23 | G22: =($F22-$E22)/$E22 -> 0.026463964
A23: 8 | B23: 风险管理 | C23: 全阶段 | D23: 4.928 | E23: 5.18 | F23: 4.86 | G23: =($F23-$E23)/$E23 -> -0.061776062
A24: 9 | B24: 评审管理 | C24: 全阶段 | D24: 7.04 | E24: 7.4 | F24: 7.04 | G24: =($F24-$E24)/$E24 -> -0.048648649
A25: 10 | B25: 配置管理 | C25: 全阶段 | D25: 10.56 | E25: 11.1 | F25: 11.12 | G25: =($F25-$E25)/$E25 -> 0.0018018018
A26: 11 | B26: 质量保证 | C26: 全阶段 | D26: 14.08 | E26: 14.8 | F26: 14.62 | G26: =($F26-$E26)/$E26 -> -0.012162162
A27: 12 | B27: 结项管理 | C27: 全阶段 | D27: 2.816 | E27: 2.96 | F27: 2.95 | G27: =($F27-$E27)/$E27 -> -0.0033783784
A28: 所有活动阶段总计 | D28: =SUM(D16:D27) -> 234.66667 | E28: =SUM(E16:E27) -> 246.66667 | F28: =SUM(F16:F27) -> 235.40216 | G28: =($F$28-$E$28)/$E$28 -> -0.045666932
A29: 注：估计值分「策划阶段」「需求阶段」两列，工作量偏差率以需求阶段估计值为基准计算
A30: 结论（原表）：工作量的估算在不同的阶段都有偏差，策划阶段估算的工作量和项目实际的偏差较大，而需求阶段偏差越来越小，说明对工作量的估算不够精确，应该采用更精确的估算方法或多参与项目增加项目经验，增强估算能力。
A32: 三、进度度量（单位：天）
A33: 阶段 | B33: 计划开始 | C33: 计划完成 | D33: 实际开始 | E33: 实际完成 | F33: 计划完成天数 | G33: 实际完成天数 | H33: 偏差天数 | I33: 进度偏差率
A34: 策划阶段 | B34: 2025-02-24 | C34: 2025-02-26 | D34: 2025-02-24 | E34: 2025-02-26 | F34: 2 | G34: 2 | H34: =$G34-$F34 -> 0 | I34: =$H34/$F34 -> 0
A35: 需求阶段 | B35: 2025-02-26 | C35: 2025-03-05 | D35: 2025-02-26 | E35: 2025-03-05 | F35: 7 | G35: 7 | H35: =$G35-$F35 -> 0 | I35: =$H35/$F35 -> 0
A36: 设计阶段 | B36: 2025-03-06 | C36: 2025-03-14 | D36: 2025-03-06 | E36: 2025-03-14 | F36: 8 | G36: 8 | H36: =$G36-$F36 -> 0 | I36: =$H36/$F36 -> 0
A37: 编码阶段 | B37: 2025-03-14 | C37: 2025-05-13 | D37: 2025-03-14 | E37: 2025-05-14 | F37: 61 | G37: 61 | H37: =$G37-$F37 -> 0 | I37: =$H37/$F37 -> 0
A38: 测试阶段 | B38: 2025-05-13 | C38: 2025-06-02 | D38: 2025-05-14 | E38: 2025-06-02 | F38: 19 | G38: 19 | H38: =$G38-$F38 -> 0 | I38: =$H38/$F38 -> 0
A39: 验收阶段 | B39: 2025-06-02 | C39: 2025-06-30 | D39: 2025-06-02 | E39: 2025-06-30 | F39: 28 | G39: 28 | H39: =$G39-$F39 -> 0 | I39: =$H39/$F39 -> 0
A40: 总计（本工作簿添加） | F40: =SUM(F34:F39) -> 125 | G40: =SUM(G34:G39) -> 125 | H40: =$G$40-$F$40 -> 0 | I40: =$H$40/$F$40 -> 0
A41: 备注：偏差天数=实际完成天数-计划完成天数；原表编码阶段实际完成(05-14)晚于计划(05-13)但天数均记61天、偏差记0，数据可信度见00说明。
A42: 结论（原表）：项目的实际进度与计划略有偏差，但进度控制在结束时间内,说明在项目进展过程中项目监控的很好，使项目能如期完成，从而提高项目策划能力。
A44: 四、成本度量（单位：元；估计源《WBS估算表》，实际源《里程碑状态报告》）
...

Sheet 03项目2度量
A1: 项目2度量数据（度量表2，编号KSSH-1102，V1.5受控） 周期：2024-09-13 ~ 2025-04-02
A2: 蓝字=原表计划/实际原值；黑字=公式（分布比例、累计偏差率、加权数、密度、探测率、修复率、效率均为公式）；绿字=引用01参数。
A4: 一、工作量度量（单位：人天；计划源项目估算表，实际源里程碑报告）
A5: 阶段 | B5: 计划工作量(人天) | C5: 实际工作量(人天) | D5: 分布比例 | E5: 累计工作量偏差率 | F5: 控制范围 | G5: 结果
A6: 立项计划 | B6: 29.355209 | C6: 31 | D6: =$C6/$C$12 -> 0.10726644 | E6: =(SUM($C$6:$C6)-SUM($B$6:$B6))/SUM($B$6:$B6) -> 0.056030641 | F6: ="±"&TEXT('01参数'!$C$4,"0%") -> ±15% | G6: 结果（原表）：工作量偏差满足控制范围，各阶段工作量分布比例也比较合理
A7: 需求开发 | B7: 32.29073 | C7: 31 | D7: =$C7/$C$12 -> 0.10726644 | E7: =(SUM($C$6:$C7)-SUM($B$6:$B7))/SUM($B$6:$B7) -> 0.005743468
A8: 系统设计 | B8: 41.097292 | C8: 40 | D8: =$C8/$C$12 -> 0.1384083 | E8: =(SUM($C$6:$C8)-SUM($B$6:$B8))/SUM($B$6:$B8) -> -0.007233867
A9: 编码实现 | B9: 102.74323 | C9: 105 | D9: =$C9/$C$12 -> 0.3633218 | E9: =(SUM($C$6:$C9)-SUM($B$6:$B9))/SUM($B$6:$B9) -> 0.0073656349
A10: 软件测试 | B10: 58.710418 | C10: 55 | D10: =$C10/$C$12 -> 0.19031142 | E10: =(SUM($C$6:$C10)-SUM($B$6:$B10))/SUM($B$6:$B10) -> -0.0083153116
A11: 交付验收 | B11: 29.355209 | C11: 27 | D11: =$C11/$C$12 -> 0.093425606 | E11: =(SUM($C$6:$C11)-SUM($B$6:$B11))/SUM($B$6:$B11) -> -0.015506918
A12: 总计 | B12: =SUM(B6:B11) -> 293.55209 | C12: =SUM(C6:C11) -> 289 | D12: =SUM(D6:D11) -> 1 | E12: =($C$12-$B$12)/$B$12 -> -0.015506918
A15: 二、规模及效率
A16: 估计规模(FP) | B16: 实际规模(FP) | C16: 规模偏差率 | D16: 功能点耗时率(人时/FP) | E16: 目标范围 | F16: 结果
A17: 328 | B17: 327 | C17: =($B$17-$A$17)/$A$17 -> -0.0030487805 | D17: =$C$12*'01参数'!$C$19/$B$17 -> 7.0703364 | E17: ="≤"&TEXT('01参数'!$C$9,"0.00") -> ≤7.15 | F17: 结果（原表）：功能点耗时率为7.07人时/FP,表现良好，达到项目度量目标
A19: 三、工期度量（单位：天，工作日口径已扣节假日；日历跨度计划189天/实际202天）
A20: 阶段 | B20: 计划开始 | C20: 计划完成 | D20: 实际开始 | E20: 实际完成 | F20: 计划工期(天) | G20: 计划累计(天) | H20: 实际工期(天) | I20: 实际累计(天) | J20: 累计工期偏差率 | K20: 控制范围 | L20: 结果
A21: 立项计划 | B21: 2024-09-13 | C21: 2024-10-09 | D21: 2024-09-13 | E21: 2024-10-09 | F21: 12 | G21: =SUM($F$21:$F21) -> 12 | H21: 12 | I21: =SUM($H$21:$H21) -> 12 | J21: =($I21-$G21)/$G21 -> 0 | K21: ="±"&TEXT('01参数'!$C$5,"0%") -> ±15% | L21: 结果（原表）：各阶段工期偏差满足控制范围，在合同规定期限内完成项目
A22: 需求开发 | B22: 2024-10-10 | C22: 2024-11-01 | D22: 2024-10-10 | E22: 2024-11-05 | F22: 17 | G22: =SUM($F$21:$F22) -> 29 | H22: 19 | I22: =SUM($H$21:$H22) -> 31 | J22: =($I22-$G22)/$G22 -> 0.068965517
A23: 系统设计 | B23: 2024-11-04 | C23: 2024-12-02 | D23: 2024-11-06 | E23: 2024-12-09 | F23: 21 | G23: =SUM($F$21:$F23) -> 50 | H23: 24 | I23: =SUM($H$21:$H23) -> 55 | J23: =($I23-$G23)/$G23 -> 0.1
A24: 编码实现 | B24: 2024-12-03 | C24: 2025-01-08 | D24: 2024-12-10 | E24: 2025-01-17 | F24: 26 | G24: =SUM($F$21:$F24) -> 76 | H24: 28 | I24: =SUM($H$21:$H24) -> 83 | J24: =($I24-$G24)/$G24 -> 0.092105263
A25: 软件测试 | B25: 2025-01-09 | C25: 2025-02-27 | D25: 2025-01-20 | E25: 2025-03-07 | F25: 30 | G25: =SUM($F$21:$F25) -> 106 | H25: 29 | I25: =SUM($H$21:$H25) -> 112 | J25: =($I25-$G25)/$G25 -> 0.056603774
A26: 交付验收 | B26: 2025-02-28 | C26: 2025-03-20 | D26: 2025-03-10 | E26: 2025-04-02 | F26: 15 | G26: =SUM($F$21:$F26) -> 121 | H26: 18 | I26: =SUM($H$21:$H26) -> 130 | J26: =($I26-$G26)/$G26 -> 0.074380165
A27: 总计 | F27: =SUM(F21:F26) -> 121 | G27: =$G$26 -> 121 | H27: =SUM(H21:H26) -> 130 | I27: =$I$26 -> 130 | J27: =($I$27-$G$27)/$G$27 -> 0.074380165
A28: 注：工期为工作日口径（已扣节假日，日历跨度计划189天/实际202天）；总计行工期偏差率原表未单列，取交付验收累计值0.0743801652892562
A30: 四、成本度量（单位：元；计划成本=计划工作量×1200元/人天推导值，实际为独立采集）
A31: 阶段 | B31: 计划成本(元) | C31: 实际成本(元) | D31: 累计偏差率 | E31: 控制范围 | F31: 结果
A32: 立项计划 | B32: 35226.251 | C32: 37200 | D32: =(SUM($C$32:$C32)-SUM($B$32:$B32))/SUM($B$32:$B32) -> 0.056030641 | E32: ="±"&TEXT('01参数'!$C$6,"0%") -> ±15% | F32: 结果（原表）：各阶段工期偏差满足控制范围，总工期偏差率满足目标范围，项目度量目标达成（原表结论文字如此，描述对象疑为工期，见dataQualityNotes）
A33: 需求开发 | B33: 38748.876 | C33: 38800 | D33: =(SUM($C$32:$C33)-SUM($B$32:$B33))/SUM($B$32:$B33) -> 0.02737236
A34: 系统设计 | B34: 49316.751 | C34: 53500 | D34: =(SUM($C$32:$C34)-SUM($B$32:$B34))/SUM($B$32:$B34) -> 0.050353057
A35: 编码实现 | B35: 123291.88 | C35: 131900 | D35: =(SUM($C$32:$C35)-SUM($B$32:$B35))/SUM($B$32:$B35) -> 0.060086059
A36: 软件测试 | B36: 70452.501 | C36: 72000 | D36: =(SUM($C$32:$C36)-SUM($B$32:$B36))/SUM($B$32:$B36) -> 0.051614743
A37: 交付验收 | B37: 35226.251 | C37: 36000 | D37: =(SUM($C$32:$C37)-SUM($B$32:$B37))/SUM($B$32:$B37) -> 0.048649782
A38: 总计 | B38: =SUM(B32:B37) -> 352262.51 | C38: =SUM(C32:C37) -> 369400 | D38: =($C$38-$B$38)/$B$38 -> 0.048649782
A39: 注：原表成本「结果」栏文字描述对象疑为工期（复制粘贴笔误），照录备考。
A41: 五、测试缺陷度量（加权权重引用01参数：致命×8、严重×4、一般×1、细微×0.5，由原始数据反推核对一致）
A42: 测试类型 | B42: 致命 | C42: 严重 | D42: 一般 | E42: 细微 | F42: 检出总数(个) | G42: 关闭缺陷数(个) | H42: 缺陷修复率 | I42: 缺陷加权数 | J42: 缺陷密度(个/FP) | K42: 缺陷探测率 | L42: 目标值 | M42: 结果
A43: 集成与系统测试 | B43: 2 | C43: 15 | D43: 17 | E43: 18 | F43: =SUM($B43:$E43) -> 52 | G43: 52 | H43: =$G43/$F43 -> 1 | I43: =$B43*'01参数'!$C$14+$C43*'01参数'!$C$15+$D43*'01参数'!$C$16+$E43*'01参数'!$C$17 -> 102 | J43: =$I43/$B$17 -> 0.31192661 | K43: =$I$43/$I$45 -> 0.78461538 | L43: ="≥"&TEXT('01参数'!$C$8,"0%") -> ≥75% | M43: 结果（原表）：缺陷探测率满足目标范围，项目度量目标达成
A44: 验收测试 | B44: 0 | C44: 0 | D44: 21 | E44: 14 | F44: =SUM($B44:$E44) -> 35 | G44: 35 | H44: =$G44/$F44 -> 1 | I44: =$B44*'01参数'!$C$14+$C44*'01参数'!$C$15+$D44*'01参数'!$C$16+$E44*'01参数'!$C$17 -> 28 | J44: =$I44/$B$17 -> 0.085626911
A45: 总计 | B45: =SUM(B43:B44) -> 2 | C45: =SUM(C43:C44) -> 15 | D45: =SUM(D43:D44) -> 38 | E45: =SUM(E43:E44) -> 32 | F45: =SUM($B$45:$E$45) -> 87 | G45: =SUM(G43:G44) -> 87 | H45: =$G$45/$F$45 -> 1 | I45: =$B$45*'01参数'!$C$14+$C$45*'01参数'!$C$15+$D$45*'01参数'!$C$16+$E$45*'01参数'!$C$17 -> 130 | J45: =$I$45/$B$17 -> 0.39755352
A46: 注：缺陷探测率=集成与系统测试加权数/总加权数（仅该行计算，验收测试与总计行原表空缺）；缺陷密度=加权数/实际规模FP。
...

Sheet 04汇总对比
A1: 跨项目度量汇总对比
A2: 项目1/项目2数值全部为跨表引用公式（绿字），随02/03表输入联动；“—”表示原表无该度量。
A4: 指标 | B4: 单位 | C4: 项目1（256FP） | D4: 项目2（327FP） | E4: 差异说明
A5: 项目规模（实际） | B5: FP | C5: ='02项目1度量'!$B$56 -> 256 | D5: ='03项目2度量'!$B$53 -> 327 | E5: P2规模约为P1的1.28倍
A6: 总工作量（实际） | B6: 人天 | C6: ='02项目1度量'!$B$58 -> 235.40216 | D6: ='03项目2度量'!$B$55 -> 289 | E6: 工作量与规模大致同比
A7: 总工期（实际） | B7: 天 | C7: ='02项目1度量'!$B$63 -> 125 | D7: ='03项目2度量'!$B$61 -> 130 | E7: P1为阶段天数合计（日历跨度127天），P2为工作日口径累计
A8: 总成本（估算/计划） | B8: 元 | C8: ='02项目1度量'!$B$65 -> 84179.733 | D8: ='03项目2度量'!$B$63 -> 352262.51 | E8: P2计划成本恰为计划工作量×1200元/人天
A9: 总成本（实际） | B9: 元 | C9: ='02项目1度量'!$B$66 -> 80451.137 | D9: ='03项目2度量'!$B$64 -> 369400 | E9: 成本口径差异巨大，横向对比需先统一人天单价
A10: 生产率 | B10: FP/人天 | C10: ='02项目1度量'!$B$60 -> 1.0875007 | D10: ='03项目2度量'!$B$58 -> 1.1314879 | E10: P2略高，可作为组织级基线区间1.09~1.13
A11: 功能点耗时率 | B11: 人时/FP | C11: ='02项目1度量'!$B$61 -> 7.3563174 | D11: ='03项目2度量'!$B$59 -> 7.0703364 | E11: P1为推算值（未在原表给出），P2达成≤7.15目标，P1按同口径略超
A12: 人天成本（实际） | B12: 元/人天 | C12: ='02项目1度量'!$B$68 -> 341.76041 | D12: ='03项目2度量'!$B$66 -> 1278.2007 | E12: 相差约3.7倍，疑成本核算口径不同（P1或仅含部分人力成本）
A13: 单功能点成本（实际） | B13: 元/FP | C13: ='02项目1度量'!$B$69 -> 314.26225 | D13: ='03项目2度量'!$B$67 -> 1129.6636 | E13: 同上，口径差异所致
A14: 工作量偏差率 | B14: % | C14: ='02项目1度量'!$B$59 -> -0.045666932 | D14: ='03项目2度量'!$B$56 -> -0.015506918 | E14: 均为负偏差（实际低于估算），P2估算更准
A15: 进度/工期偏差率 | B15: % | C15: ='02项目1度量'!$B$64 -> 0 | D15: ='03项目2度量'!$B$62 -> 0.074380165 | E15: P1全程记0（存在抹平嫌疑，见dataQualityNotes），P2累计延误7.4%在±15%控制内
A16: 成本偏差率 | B16: % | C16: ='02项目1度量'!$B$67 -> -0.044293275 | D16: ='03项目2度量'!$B$65 -> 0.048649782 | E16: P1节支4.4%（疑折算），P2超支4.9%在控制内
A17: 规模偏差率 | B17: % | C17: — | D17: ='03项目2度量'!$B$57 -> -0.0030487805 | E17: P1未给出总体估算vs实际口径（测试阶段估算187 vs 最终实际256，差27%）
A18: 缺陷密度 | B18: 个/FP | C18: — | D18: ='03项目2度量'!$B$68 -> 0.39755352 | E18: P1无缺陷度量表
A19: 缺陷探测率 | B19: % | C19: — | D19: ='03项目2度量'!$B$69 -> 0.78461538 | E19: P2达成≥75%目标；P1无此度量

Sheet 05监控报告
A1: 项目度量红绿灯监控报告
A2: 红黄绿判定规则：|偏差率|≤阈值×0.6 为绿色（正常），阈值×0.6<|偏差率|≤阈值 为黄色（预警），|偏差率|>阈值 为红色（超限）。工作量/进度/成本偏差阈值±15%（绿区≤9%）、规模偏差阈值±10%（绿区≤6%）；达标线类指标：缺陷探测率≥75%、评审效率≥0.75个/人时、功能点耗时率≤7.15人时/FP，达标为绿、未达标为红。
A3: 指标值与阈值均为跨表引用（绿字）；状态列为公式，随01参数阈值联动；最右两列为自动结论的辅助记录列。
A4: 判定公式：偏差型 =IF(ABS(值)<=阈值×系数,"● 正常",IF(ABS(值)<=阈值,"▲ 预警","✖ 超限"))；达标型按≥/≤方向判达标。
A5: 序号 | B5: 项目 | C5: 维度/指标 | D5: 指标值 | E5: 阈值/目标 | F5: 判定类型 | G5: 状态 | H5: 结论建议 | I5: 超限记录 | J5: 预警记录
A6: 1 | B6: P1 | C6: 工作量偏差率 | D6: ='02项目1度量'!$B$59 -> -0.045666932 | E6: ='01参数'!$C$4 -> 0.15 | F6: 偏差型± | G6: =IF(ABS($D6)<=$E6*'01参数'!$C$11,"● 正常",IF(ABS($D6)<=$E6,"▲ 预警","✖ 超限")) -> ● 正常 | H6: 实际低于估算4.6%，绿区；注意P1偏差基准为需求阶段估计值 | I6: =IF(LEFT($G6,1)="✖",$B6&$C6,"") | J6: =IF(LEFT($G6,1)="▲",$B6&$C6,"")
A7: 2 | B7: P1 | C7: 进度偏差率 | D7: ='02项目1度量'!$B$64 -> 0 | E7: ='01参数'!$C$5 -> 0.15 | F7: 偏差型± | G7: =IF(ABS($D7)<=$E7*'01参数'!$C$11,"● 正常",IF(ABS($D7)<=$E7,"▲ 预警","✖ 超限")) -> ● 正常 | H7: 全程记0偏差，绿区；但编码阶段实际完成晚于计划1天仍记0，疑被抹平，可信度存疑 | I7: =IF(LEFT($G7,1)="✖",$B7&$C7,"") | J7: =IF(LEFT($G7,1)="▲",$B7&$C7,"")
A8: 3 | B8: P1 | C8: 成本偏差率 | D8: ='02项目1度量'!$B$67 -> -0.044293275 | E8: ='01参数'!$C$6 -> 0.15 | F8: 偏差型± | G8: =IF(ABS($D8)<=$E8*'01参数'!$C$11,"● 正常",IF(ABS($D8)<=$E8,"▲ 预警","✖ 超限")) -> ● 正常 | H8: 节支4.4%，绿区；各里程碑偏差率高度一致，实际成本疑按估算折算，建议实采核对 | I8: =IF(LEFT($G8,1)="✖",$B8&$C8,"") | J8: =IF(LEFT($G8,1)="▲",$B8&$C8,"")
A9: 4 | B9: P1 | C9: 功能点耗时率 | D9: ='02项目1度量'!$B$61 -> 7.3563174 | E9: ='01参数'!$C$9 -> 7.15 | F9: 达标型≤ | G9: =IF($D9<=$E9,"● 达标","✖ 未达标") -> ✖ 未达标 | H9: 7.36人时/FP为推算值（原表未给出），略超7.15目标；横向对比需先统一口径 | I9: =IF(LEFT($G9,1)="✖",$B9&$C9,"") -> P1功能点耗时率 | J9: =IF(LEFT($G9,1)="▲",$B9&$C9,"")
A10: 5 | B10: P2 | C10: 工作量偏差率 | D10: ='03项目2度量'!$B$56 -> -0.015506918 | E10: ='01参数'!$C$4 -> 0.15 | F10: 偏差型± | G10: =IF(ABS($D10)<=$E10*'01参数'!$C$11,"● 正常",IF(ABS($D10)<=$E10,"▲ 预警","✖ 超限")) -> ● 正常 | H10: -1.6%，绿区，估算准确，各阶段分布比例合理 | I10: =IF(LEFT($G10,1)="✖",$B10&$C10,"") | J10: =IF(LEFT($G10,1)="▲",$B10&$C10,"")
A11: 6 | B11: P2 | C11: 规模偏差率 | D11: ='03项目2度量'!$B$57 -> -0.0030487805 | E11: ='01参数'!$C$7 -> 0.1 | F11: 偏差型± | G11: =IF(ABS($D11)<=$E11*'01参数'!$C$11,"● 正常",IF(ABS($D11)<=$E11,"▲ 预警","✖ 超限")) -> ● 正常 | H11: -0.3%，绿区，规模基线控制好 | I11: =IF(LEFT($G11,1)="✖",$B11&$C11,"") | J11: =IF(LEFT($G11,1)="▲",$B11&$C11,"")
A12: 7 | B12: P2 | C12: 工期偏差率 | D12: ='03项目2度量'!$B$62 -> 0.074380165 | E12: ='01参数'!$C$5 -> 0.15 | F12: 偏差型± | G12: =IF(ABS($D12)<=$E12*'01参数'!$C$11,"● 正常",IF(ABS($D12)<=$E12,"▲ 预警","✖ 超限")) -> ● 正常 | H12: 累计+7.4%，绿区；系统设计阶段曾达10%触及黄区后收敛，设计/编码阶段需设检查点 | I12: =IF(LEFT($G12,1)="✖",$B12&$C12,"") | J12: =IF(LEFT($G12,1)="▲",$B12&$C12,"")
A13: 8 | B13: P2 | C13: 成本偏差率 | D13: ='03项目2度量'!$B$65 -> 0.048649782 | E13: ='01参数'!$C$6 -> 0.15 | F13: 偏差型± | G13: =IF(ABS($D13)<=$E13*'01参数'!$C$11,"● 正常",IF(ABS($D13)<=$E13,"▲ 预警","✖ 超限")) -> ● 正常 | H13: 超支+4.9%，绿区；实际成本全程高于计划（最高+6%），更大规模项目可能放大为超限 | I13: =IF(LEFT($G13,1)="✖",$B13&$C13,"") | J13: =IF(LEFT($G13,1)="▲",$B13&$C13,"")
A14: 9 | B14: P2 | C14: 功能点耗时率 | D14: ='03项目2度量'!$B$59 -> 7.0703364 | E14: ='01参数'!$C$9 -> 7.15 | F14: 达标型≤ | G14: =IF($D14<=$E14,"● 达标","✖ 未达标") -> ● 达标 | H14: 7.07≤7.15，达标 | I14: =IF(LEFT($G14,1)="✖",$B14&$C14,"") | J14: =IF(LEFT($G14,1)="▲",$B14&$C14,"")
A15: 10 | B15: P2 | C15: 缺陷探测率 | D15: ='03项目2度量'!$B$69 -> 0.78461538 | E15: ='01参数'!$C$8 -> 0.75 | F15: 达标型≥ | G15: =IF($D15>=$E15,"● 达标","✖ 未达标") -> ● 达标 | H15: 78.5%≥75%，达标；缺陷加权集中于集成与系统测试（致命2/严重15），评审与单测宜前移 | I15: =IF(LEFT($G15,1)="✖",$B15&$C15,"") | J15: =IF(LEFT($G15,1)="▲",$B15&$C15,"")
A16: 11 | B16: P2 | C16: 评审效率 | D16: ='03项目2度量'!$B$70 -> 0.75757576 | E16: ='01参数'!$C$10 -> 0.75 | F16: 达标型≥ | G16: =IF($D16>=$E16,"● 达标","✖ 未达标") -> ● 达标 | H16: 0.758≥0.75，达标 | I16: =IF(LEFT($G16,1)="✖",$B16&$C16,"") | J16: =IF(LEFT($G16,1)="▲",$B16&$C16,"")
A18: 自动统计 | B18: ● 正常/达标 | D18: =SUMPRODUCT(--(LEFT($G$6:$G$16,1)="●")) -> 10 | E18: ▲ 预警 | F18: =SUMPRODUCT(--(LEFT($G$6:$G$16,1)="▲")) -> 0 | G18: ✖ 超限/未达标 | H18: =SUMPRODUCT(--(LEFT($G$6:$G$16,1)="✖")) -> 1
A19: 自动结论 | B19: ="本次监控共 "&COUNTA($G$6:$G$16)&" 项指标：正常/达标 "&$D$18&" 项、预警 "&$F$18&" 项、超限/未达标 "&$H$18&" 项。"&IF($H$18=0,"无超限/未达标项。","超限/未达标项："&_xlfn.TEXTJOIN("、",TRUE(),$I$6:$I$16)&"。")&IF($F$18=0,"","预警项："&_xlfn.TEXTJOIN("、",TRUE(),$J$6:$J$16)&"。") -> 本次监控共 11 项指标：正常/达标 10 项、预警 0 项、超限/未达标 1 项。超限/未达标项：P1功能点耗时率。
A21: 总体研判（来自分析报告）
B22: 两个项目的工作量、进度、成本偏差均未突破±15%控制范围，总体受控。P1三项偏差全部落在绿区（工作量-4.6%、成本-4.4%、进度0），但其进度零偏差与成本高度规则化的数据存在采集质量疑点，结论可信度打折。P2数据链完整且自洽：工作量-1.6%、成本+4.9%为绿，累计工期偏差在系统设计阶段达到10%触及黄区后收敛至7.4%回到绿区，缺陷探测率78.5%、评审效率0.758、功能点耗时率7.07人时/FP三项质量指标全部达标。P2可作为组织级度量基线的主参照，P1数据需先治理后使用。
A24: 主要风险
A25: R1 | B25: P1度量数据真实性存疑（成本疑按固定比例折算、进度偏差被抹平、编码阶段计划天数疑按实际回填），以其为基线会系统性低估偏差风险
A26: R2 | B26: P1规模在测试阶段估算187FP、验收结项实际256FP，跳变27%且无估算对照，提示需求蔓延或功能点计数口径前后不一
A27: R3 | B27: P2系统设计、编码实现阶段累计工期偏差达10%、9.2%，逼近15%阈值的黄区边界，同类项目若前期延误叠加可能突破控制范围
A28: R4 | B28: P2成本累计偏差随阶段推进最高至6%（编码实现），实际成本全程高于计划，规模再大的项目可能放大为红区超支
A29: R5 | B29: 两项目人天成本相差约3.7倍（342 vs 1278元/人天），成本核算口径不统一，跨项目成本对标和报价参考失真
A30: R6 | B30: P2缺陷加权数102集中在集成与系统测试（致命2、严重15），前移评审与单元测试投入不足的信号
A32: 改进建议
A33: S1 | B33: 统一功能点计数与成本采集口径：实际成本必须实采（工时×费率+费用），禁止按估算折算回填；人天单价组织级统一定义
A34: S2 | B34: 建立规模基线变更管理：阶段间规模变化超过±10%必须走变更评审并同步修订工作量/成本/工期基线，避免P1式的验收期规模跳变
A35: S3 | B35: 对设计、编码阶段设置进度里程碑检查点（P2经验：累计偏差在设计阶段即达10%），偏差进入黄区即启动赶工或范围裁剪决策
A36: S4 | B36: 以P2为参照建立组织级基线：生产率1.09~1.13 FP/人天、功能点耗时率7.07~7.36人时/FP，用于新项目（如本供水营销管理系统24个二级功能）的估算复核
A37: S5 | B37: 度量数据入库前增加完整性与逻辑校验：项目属性表必填项校验、日期与天数一致性校验（实际完成晚于计划则偏差天数不得为0）、偏差率重算比对
A38: S6 | B38: 加强评审与测试前移：参照P2评审效率0.758个/人时的水平配置评审工时，将严重缺陷拦截在集成测试之前以降低缺陷加权数

Sheet 06功能分解
A1: 《供水营销管理系统》功能分解（WBS）全清单 来源：需求规格说明书（srs_full.txt）
A3: 模块数 | B3: =SUMPRODUCT(1/COUNTIF($A$9:$A$35,$A$9:$A$35)) -> 8 | C3: 功能数 | D3: =COUNTA($C$9:$C$35) -> 27 | E3: P1数 | F3: =COUNTIF($E$9:$E$35,"P1") -> 19
A4: 优先级映射：SRS优先级1→P1 高（核心必备）；2→P2 中高；5→P3 一般 | E4: P2数 | F4: =COUNTIF($E$9:$E$35,"P2") -> 2
A5: 统计为COUNTA/COUNTIF公式，随清单增删联动 | E5: P3数 | F5: =COUNTIF($E$9:$E$35,"P3") -> 6
A7: （首行已冻结，表头行已开启自动筛选）
A8: 模块编号 | B8: 模块名称 | C8: 功能编号 | D8: 功能名称 | E8: 优先级 | F8: 优先级说明 | G8: SRS章节 | H8: 细化功能描述 | I8: 主要输入 | J8: 主要输出 | K8: 验收要点 | L8: 备注问题
A9: M1 | B9: 档案基础数据 | C9: FR-1.1 | D9: 用户状态 | E9: P1 | F9: 高（核心必备） | G9: 4.1.1 | H9: 维护用水户生命周期状态字典。管理对象为用户状态代码表，字段应含：状态编码（唯一、创建后不可改）、状态名称（如正常、报停、暂停、违章、销户）、是否抄表标志、是否计费标志、是否允许缴费标志、启用/停用标志、排序号、备注。规则：状态被客户档案引用后禁止删除、只能停用；『是否抄表』决定抄表计划是否为该状态用户生成抄表任务；『是否允许缴费』供公众缴费平台配置（4.3.4限制用户状态）引用，拦截不允许状态用户的线上缴费；『是否计费』决定开账时是否生成水费账单。 | I9: 状态编码；状态名称；是否抄表标志；是否计费标志；是否允许缴费标志；启用/停用标志；备注 | J9: 用户状态列表（含各状态引用户数）；新增/修改/启停用操作结果提示 | K9: 新增编码重复的状态时被系统拒绝并给出明确提示 将某状态『是否抄表』置否后，该状态用户不再出现在新生成的抄表计划中 被至少1户引用的状态执行删除操作被拒绝，执行停用成功且新档案下拉不再出现该状态 | L9: SRS操作序列写『点击用户管理，新增』，应为『用户状态管理』，疑为编写笔误；SRS未定义任何字段与状态取值清单，是否计费/是否允许缴费标志为本次细化补充，需与业务确认。
A10: M1 | B10: 档案基础数据 | C10: FR-1.2 | D10: 用户分类 | E10: P3 | F10: 一般 | G10: 4.1.2 | H10: 维护用户性质分类字典，用于统计与政策口径管理。字段应含：分类编码（唯一）、分类名称（如居民、非居民、单位、趸售、特困减免户）、上级分类（支持树形）、启用/停用标志、备注。规则：分类被客户档案引用后禁止删除；用户分类可作为水价方案、报表统计、优惠适用范围的筛选维度；与行业分类（FR-1.4）职责区分：用户分类描述『用户性质』，行业分类描述『用水性质』。 | I10: 分类编码；分类名称；上级分类；启停用标志；备注 | J10: 用户分类列表；操作结果提示 | K10: 新增两级分类后档案立户界面可级联选择 删除被引用分类被拒绝，停用后新档案不可再选择该分类 | L10: SRS未说明用户分类与水价、优惠、报表的关联关系，本细化按营销系统惯例补充，需业务确认。
A11: M1 | B11: 档案基础数据 | C11: FR-1.3 | D11: 抄表周期 | E11: P1 | F11: 高（核心必备） | G11: 4.1.3 | H11: 维护抄表周期字典，驱动抄表计划的生成节奏。字段应含：周期编码、周期名称（如月抄、双月抄、季抄）、间隔月数、每期例抄日（日历日或工作日偏移）、启用/停用标志、备注。规则：周期挂接在表册上（一个表册一个周期），『抄表周期只能以表册为单位修改』即不允许对单户改周期，改周期须整册调整；被表册引用的周期禁止删除；周期+例抄日决定表册到期日，系统按到期日自动生成本期抄表计划任务。 | I11: 周期编码；周期名称；间隔月数；例抄日；启停用标志 | J11: 抄表周期列表（含引用表册数）；操作结果提示 | K11: 新建『双月抄』周期并挂接表册后，系统每2个月按例抄日生成一次该册抄表计划 对单个用户修改抄表周期的入口不存在（只能通过表册整体调整） 删除被引用周期被系统拒绝 | L11: 3.3明确『抄表周期只能以表册为单位修改』的约束，但4.1.3正文未重申，该规则需在表册管理（FR-2.2）中实现联动控制；SRS未定义例抄日概念，为细化补充。
A12: M1 | B12: 档案基础数据 | C12: FR-1.4 | D12: 行业分类 | E12: P3 | F12: 一般 | G12: 4.1.4 | H12: 维护用水性质的行业分类字典，支持大类-小类两级结构（SRS操作序列提到『行类大小分类』）。字段应含：大类编码/名称（商业、工业、居民、特种等）、小类编码/名称、所属大类、启用/停用标志、备注。规则：行业分类挂接客户档案，用于用水性质统计报表与特种行业水价（如洗车、洗浴等特种用水执行特种水价）；被档案引用的分类禁止删除；特种行业类别应可被水价方案引用。 | I12: 大类编码；大类名称；小类编码；小类名称；启停用标志 | J12: 行业分类列表（大类/小类树，含挂接户数）；操作结果提示 | K12: 可建立『商业-餐饮』两级分类并在档案立户时级联选择 按行业分类出具用水量统计时口径与档案挂接一致 | L12: SRS正文未明确两级结构的字段与水价联动，『行类大小分类』表述含糊，需与业务确认特种行业是否直接驱动水价。
A13: M1 | B13: 档案基础数据 | C13: FR-1.5 | D13: 优惠类型 | E13: P1 | F13: 高（核心必备） | G13: 4.1.5 | H13: 维护水费优惠政策字典。字段应含：优惠编码、优惠名称（如低保户减免、军烈属优惠、特困减免）、优惠方式（比例折扣/每期定额金额减免/每期定量水量减免）、优惠值、适用收费类型（水费/污水费）、适用用户分类、生效日期、失效日期、启用/停用标志、审批依据备注。规则：优惠类型在档案管理的水价信息处挂接到具体用户；算费开账时按优惠方式参与账单金额计算（先算原价再按优惠冲减，账单需保留优惠前后金额明细）；被档案引用的优惠禁止删除；过期优惠自动停止参与算费。 | I13: 优惠编码；优惠名称；优惠方式；优惠值；适用收费类型；适用用户分类；生效日期；失效日期；启停用标志 | J13: 优惠类型列表（含挂接户数）；操作结果提示 | K13: 挂接比例折扣优惠的用户下期账单金额=原价×折扣，且账单保留优惠明细 优惠到失效日期后的下一账期不再冲减 删除被引用优惠被系统拒绝 | L13: SRS未定义『明细方式』的具体枚举，比例/定额/定量三种方式为细化推导；优惠与阶梯水价叠加时的计算顺序SRS未规定，须补充算费规则文档。
A14: M2 | B14: 抄表基础模块 | C14: FR-2.1 | D14: 抄表员管理 | E14: P1 | F14: 高（核心必备） | G14: 4.2.1 | H14: 维护抄表员基础档案并与表册、掌上机、登录账号关联。字段应含：抄表员编号（唯一，可由系统自动生成）、姓名、所属营业所/抄表区域、联系电话、在职状态（在职/离职/停用）、关联系统登录账号、绑定掌上机设备号、备注。规则：一名抄表员可负责多个表册，一个表册同一时间只归属一名抄表员；有在管表册的抄表员不允许直接删除，须先将表册移交他人；离职/停用抄表员不再出现在表册分配与抄表任务下发范围内。 | I14: 姓名；所属营业所/区域；联系电话；关联登录账号；掌上机设备号；在职状态 | J14: 抄表员列表（含在管表册数）；操作结果提示 | K14: 新增抄表员后可在表册管理中被选为责任抄表员 删除在管表册>0的抄表员被系统拒绝 按区域查询结果与档案归属一致 | L14: SRS操作项中的『生成』含义未解释（推断为自动生成抄表员编号或由账号同步生成），需与业务确认；输出栏『展现当面系统』系错别字（当前）。
A15: M2 | B15: 抄表基础模块 | C15: FR-2.2 | D15: 表册管理 | E15: P1 | F15: 高（核心必备） | G15: 4.2.2 | H15: 维护表册（按抄表路线组织的用户集合，抄表与批量销账的基本单位）。字段应含：表册编号（唯一）、表册名称、所属区域/营业所、责任抄表员、抄表周期（引用FR-1.3）、例抄日、册内户数（系统统计）、表册状态（启用/停用/待移交）、备注。规则：抄表周期只能以表册为单位修改（3.3约束在此落地）；新立户用户必须归入某表册后才能进入抄表计划；用户可在表册间调拨（换册）并保留调拨记录；表册到期时系统按其周期与例抄日自动生成本期抄表计划；批量销账（FR-4.2）以表册号为查询入口。 | I15: 表册编号；表册名称；所属区域/营业所；责任抄表员；抄表周期；例抄日；状态 | J15: 表册列表（含表册户数）；表册明细（册内用户清单）；操作结果提示 | K15: 新增表册并归入用户后，列表户数统计与实际归户数一致 修改表册周期后整册用户下期抄表计划日期同步变化，且不存在对单户改周期的入口 删除非空表册被系统拒绝 | L15: SRS功能描述过于简略（仅一句『表册信息的管理』），未定义表册与档案、抄表计划、批量销账的关联，本细化为核心补充内容。
A16: M2 | B16: 抄表基础模块 | C16: FR-2.3 | D16: 表册顺序调整 | E16: P1 | F16: 高（核心必备） | G16: 4.2.3 | H16: 调整表册内各户号的抄表顺序号，使抄表路线与实地行走路线一致。管理对象为表册-用户关系中的『册内抄表顺序号』字段。规则：顺序号在同一表册内唯一、连续（或允许留空隙由系统重排）；支持单户改号、上移/下移、拖拽排序、区间批量重排四种方式；调整后手工抄表界面（FR-7.1）与掌上机下载任务按新顺序展示；新入册用户默认排在册尾；调整操作留痕（操作人、时间、前后顺序）。 | I16: 表册号；户号；新抄表顺序号（或移动操作） | J16: 调整后的册内用户顺序列表；操作结果提示与变更日志 | K16: 调整顺序保存后，手工抄表界面按新顺序逐户展示 同册顺序号冲突时保存被拒绝并明确定位 顺序调整存在可查询的操作日志 | L16: SRS该节输入、输出均填『无』，属文档缺陷——实际输入应为册内户号与目标顺序号，输出应为调整后的顺序列表；与掌上机已下发任务的同步策略SRS未提及。
A17: M3 | B17: 收费数据基础 | C17: FR-3.1 | D17: 收费类型 | E17: P1 | F17: 高（核心必备） | G17: 4.3.1 | H17: 维护费用科目字典。字段应含：收费类型编码（唯一）、收费类型名称（如水费、污水处理费、垃圾费、违约金/滞纳金、工程款、预存款）、是否允许线上渠道缴纳、销账冲抵优先顺序、对应票据类型（引用FR-5.1）、是否参与滞纳金计算、启用/停用标志。规则：账单按收费类型分项记账与开票；公众缴费平台配置（FR-3.4）可按收费类型限制线上可缴项目；销账时按冲抵优先顺序依次核销多项费用；被账单或渠道配置引用的类型禁止删除。 | I17: 收费类型编码；收费类型名称；是否允许线上缴纳；冲抵优先顺序；对应票据类型；是否参与滞纳金计算；启停用标志 | J17: 收费类型列表；操作结果提示 | K17: 销账时多项费用按配置的冲抵顺序依次核销 线上禁缴的收费类型在公众缴费平台查询结果中不可缴 删除被引用类型被系统拒绝 | L17: SRS仅一句描述，冲抵顺序、票据联动、滞纳金参与规则均为细化补充，需业务确认；水费/污水费拆分记账口径未定义。
A18: M3 | B18: 收费数据基础 | C18: FR-3.2 | D18: 收费网点 | E18: P3 | F18: 一般 | G18: 4.3.2 | H18: 维护线下收费网点（营业厅）档案。字段应含：网点编码（唯一）、网点名称、所属区域/分公司、地址、负责人、联系电话、营业时间、支持业务（收费/开票/预存/退费）、启用/停用标志。规则：柜员收费流水必须归属某网点，作为网点日结、长短款核对与收入统计的口径；网点停用后不再受理新流水但历史流水可查；ATM收费机（FR-3.3）挂接在网点之下。 | I18: 网点编码；网点名称；所属区域；地址；负责人；联系电话；启停用标志 | J18: 区域对应收费网点列表；操作结果提示 | K18: 柜台收费流水均带网点归属且网点日结汇总与流水明细一致 停用网点不再出现在柜员登录可选网点中 | L18: SRS未说明网点与柜员、日结的关系，为细化补充。
A19: M3 | B19: 收费数据基础 | C19: FR-3.3 | D19: Atm收费机 | E19: P3 | F19: 一般 | G19: 4.3.3 | H19: 维护线下ATM自助缴费机设备档案。字段应含：设备编号（唯一）、设备名称、所属收费网点/安装位置、终端标识/IP、支持缴费方式（现金/银行卡/扫码）、是否支持打印票据、设备状态（在线/离线/停用/维修）、投产日期。规则：自助机缴费流水按设备编号归集，参与渠道对账与网点日结；设备停用后终端登录被拒绝；设备状态变化留日志供运维排查。 | I19: 设备编号；设备名称；所属网点/位置；终端标识/IP；支持缴费方式；设备状态 | J19: 自助缴费机列表（含状态）；操作结果提示 | K19: 新增设备后该终端可正常登录受理缴费 按设备编号可汇总查询其全部缴费流水 停用设备终端登录被拒绝 | L19: SRS未涉及自助机与系统的通讯协议、现金钞箱管理与差错处理，属需求缺口。
... A35: M8 | B35: 外部接口 | C35: FR-8.3 | D35: 对账 | E35: P1 | F35: 高（核心必备） | G35: 5.2.3 | H35: 银行日终生成代收对账文件并上传至约定目录后，调用本接口通知平台取文件对账。入参：bankentityno（银行实体编号）、filedate（对账文件日期yyyyMMdd）、filepath（对账文件存放相对路径，如/upload/20160829）、filetype（文件类型，DSDZ=代收对账文本）、extend（预留扩展）。平台收到通知后：校验渠道合法与文件可读，异步解析对账文件，按bankno将文件内每笔代收记录与平台渠道销账流水（FR-8.2）逐笔勾对，产出对账结果：平账、长款（银行有平台无）、短款（平台有银行无）、金额不符四类，差错记录进入差错处理队列（补账/冲正/人工处理），生成日对账报告供财务复核，对账平衡后确认资金划转入账。 | I35: bankentityno（string，10，必填）；filedate（string，8，必填，yyyyMMdd）；filepath（string，128，必填，对账文件相对路径）；filetype（string，8，必填，DSDZ=代收对账文本）；extend（json串，选填，预留扩展） | J35: code、msg（通知受理结果）；data数组：bankentityno、filedate、filepath、filetype、extend；平台侧产物：日对账报告、差错明细队列 | K35: 对账文件总笔数=平账+长款+短款+金额不符笔数之和，账目闭合 文件不可读时返回失败且银行重传后可重新发起对账 差错记录均有处理状态跟踪直至闭环 同一filedate重复通知不产生重复入账 | L35: SRS该节首行『呼入管理信息查询接口』为呼叫中心类文档复制残留；对账文件内部格式（字段、分隔符、汇总行）全文未定义，仅有文件类型DSDZ代号；对账结果如何反馈银行（回盘文件或接口）缺失；3.1提及的『银行划帐』（托收）模块与本代收对账的关系未说明（见expansion）。
A38: 范围缺口：SRS 3.1/3.2 提及但第4章未详述的模块（扩展建议，不计入上方27项清单）
A39: 模块 | B39: SRS线索/缺失原因 | C39: 建议补充功能
A40: 帐务管理 | B40: 3.1功能清单提及、3.2总体功能描述『每笔费用可由财务进行处理』，但3.3清单与第4章均未详述；算费开账是抄表到收费链路的中枢，缺失将导致账单来源无定义。 | C40: · 算费开账（按抄表记录+水价+阶梯+优惠生成账单，含污水费等附加费项） · 水价方案管理（分类水价、阶梯水价、特种水价与调价生效） · 滞纳金/违约金计算规则配置（起算日、费率、封顶） · 水量异常减免与污水费缓缴审批（3.2明确提及） · 账单调整/冲红与重开账 · 应收账款账龄与欠费催缴管理 · 网点/柜员日结与财务复核入账
A41: 掌上机抄表管理 | B41: 3.1提及且3.2抄表管理描述『提供抄表机抄表』，但第4章仅有导入侧（4.7.3），任务下载、外勤采集、回传的闭环未详述。 | C41: · 抄表任务下发（按表册/抄表顺序生成掌上机任务包） · 掌上机设备注册与绑定管理（设备号-抄表员） · 外勤抄表采集（读数、异常标记、拍照、GPS定位） · 抄表数据回传与断点续传 · 抄见率/漏抄监控与任务进度看板
A42: 银行划帐 | B42: 3.1提及、3.2收费管理描述『通过银行托收…实时代收、代扣』，但第4章无对应功能，5.2仅覆盖银行实时代收接口，批量托收划扣未定义。 | C42: · 用户银行账户签约管理（缴费方式变更、银行信息变更，3.2档案管理提及） · 托收批次生成（按账期汇总签约用户欠费生成划扣文件） · 托收文件报盘/回盘处理（成功销账、失败原因回写） · 托收失败转催缴与二次托收 · 托收对账与资金到账勾稽
A43: 系统报表 | B43: 3.1提及但全文无任何报表定义；3.2抄表管理提到『水量异常的抄表数据报表监控』亦无落地功能。 | C43: · 抄表报表（抄见率、异常水量监控、估抄率、漏抄清单） · 收费报表（日/月收费汇总、分渠道/网点/柜员统计、日结单） · 欠费报表（欠费清单、账龄分析、催缴效果） · 售水量与产销差统计报表 · 发票使用与开票汇总报表 · 报表导出（Excel/PDF）与定时生成推送
A44: 系统管理 | B44: 3.1提及未详述；6.3安全性要求（身份鉴别、口令策略、登录失败处理、角色权限、审计）均需系统管理功能承载，否则安全需求无实现载体。 | C44: · 组织机构与区域管理（营业所/分公司） · 用户账号管理（唯一性、口令复杂度≥8位3类字符、定期更换、登录失败锁定——对应6.3.1） · 角色权限管理（功能权限、数据权限、柜台授权审批权限） · 操作日志与安全审计（应用层行为审计，对应6.3.1审计要求） · 系统参数配置（滞纳金参数、异常水量倍数N、预存抵扣开关等） · 数据字典统一维护入口
A45: 档案管理（业务办理部分） | B45: 3.2详述了立户、销户、过户、改表、缴费方式变更、银行信息变更及档案变更跟踪，但第4章仅覆盖档案『基础数据』字典，立户等核心业务流程未给出场景描述表。 | C45: · 报装立户（生成户号、绑定水表、水价与优惠设定、归入表册） · 销户/报停/复装 · 过户与用水性质变更 · 换表/改表业务（联动换表信息影响抄表） · 缴费方式与银行信息变更 · 档案变更历史跟踪查询
A46: 水表管理（表务全生命周期） | B46: 3.2表务管理详述了入库检验、表身号录入、出库、周期更换、拆表换表、故障、检定与周检，但第4章仅覆盖水表『基础数据』字典，表务台账流程未详述。 | C46: · 水表入库与到货检验（表身号批量录入） · 水表出库领用与装表关联 · 周期换表计划（按口径换表周期/换表读数自动生成，联动FR-6.2） · 拆表/换表/故障处理登记 · 水表检定与周检管理（联动FR-6.3参数） · 水表全生命周期状态跟踪查询

Sheet 07质量检查
A1: 《供水营销管理系统》SRS质量检查问题清单
A2: 总评：该SRS最严重的系统性问题是多系统模板拼接残留：编写目的出现「微ME」项目名，标准依据列的是语义网RDF/OWL/XML，安全性章节整体照搬医疗行业模板（「双向转诊系统」「患者信息/医疗影像」），接口章节夹带通信与呼叫中心术语（「单个A号码新增」「号码池/隐号网关」「呼入管理」），暴露出文档由多份异源模板拼接且未经通读校对。其次是关键指标自相矛盾：6.2性能指标三套吞吐量口径相差40倍、响应时间1.5秒与3秒并存，第8章AWS部署与6.3自主可控测评要求直接冲突，均属开发前必须裁决的架构级问题。第三是需求覆盖严重不完整：3.1宣称的11个模块仅7个在第4章展开，帐务管理、银行划帐、系统报表、系统管理、掌上机抄表近半个系统无任何需求描述，算费规则、角色权限矩阵、数据字典、业务流程图、接口错误码与冲红接口全部缺失。终审共确认41项问题（高18、中16、低7），其中信息缺失14项、模板残留7项居前两位。返工建议：先由业务方裁决范围口径与部署选型两项架构级矛盾，再集中清理全部模板残留与指标矛盾，补齐范围声明、术语表、需求编号、数据字典与角色权限等结构性缺失。评审结论：有条件通过——须完成全部18项高严重度问题整改并复审确认后，方可进入设计阶段；中低严重度问题应在下一版文档中一并修订。
A4: 问题总数 | B4: =COUNTA($A$10:$A$50) -> 41 | C4: 高 | D4: =COUNTIF($D$10:$D$50,"高") -> 18 | E4: 中 | F4: =COUNTIF($D$10:$D$50,"中") -> 16 | G4: 低 | H4: =COUNTIF($D$10:$D$50,"低") -> 7
A5: 前后矛盾 | B5: =COUNTIF($C$10:$C$50,"前后矛盾") -> 5 | C5: 信息缺失 | D5: =COUNTIF($C$10:$C$50,"信息缺失") -> 14 | E5: 歧义 | F5: =COUNTIF($C$10:$C$50,"歧义") -> 2 | G5: 模板残留 | H5: =COUNTIF($C$10:$C$50,"模板残留") -> 7
A6: 技术性错误 | B6: =COUNTIF($C$10:$C$50,"技术性错误") -> 1 | C6: 错别字笔误 | D6: =COUNTIF($C$10:$C$50,"错别字笔误") -> 4 | E6: 模糊不可验证 | F6: =COUNTIF($C$10:$C$50,"模糊不可验证") -> 4 | G6: 术语不一致 | H6: =COUNTIF($C$10:$C$50,"术语不一致") -> 4
A8: （统计均为COUNTIF公式；严重度列条件格式：高=红底白字、中=黄底、低=灰字；首行冻结+自动筛选）
A9: 编号 | B9: 章节位置 | C9: 类别 | D9: 严重度 | E9: 原文摘录 | F9: 问题说明 | G9: 修改建议 | H9: 状态
A10: Q-001 | B10: 3.1 供水营销管理系统简介 / 3.3 系统功能清单（对照3.2与第4章） | C10: 前后矛盾 | D10: 高 | E10: 营销平台提供：档案管理、水表管理、抄表管理、营业收费、票据管理、帐务管理、掌上机抄表管理、银行划帐、系统报表、系统管理、外部接口。 | F10: 3.1宣称11个模块，3.2只描述了4个（档案/抄表/收费/表务），3.3功能清单与第4章仅覆盖7个一级模块24个二级功能（档案基础数据、抄表基础模块、收费数据基础、柜台收费业务、票据基础信息、水表基础数据、抄表计划）。帐务管理、掌上机抄表管理、银行划帐、系统报表、系统管理5个模块在3.3和第4章均无任何需求展开——接近半个系统无法据此设计、开发和测试；其中银行划帐（托收/代扣）也不同于5.2的银行代收接口，无任何补位。需求范围前后不一致，开发、报价、验收范围无法确定。 | G10: 统一三处口径并明确范围声明，如：「本期需求范围为7个一级模块24个二级功能及3个银行代收接口；帐务管理、银行划帐、系统报表、系统管理、掌上机抄表为后续阶段范围」，并同步修订3.1/3.2/3.3与第4章使之一致；若5个模块属本期范围，则须在3.3和第4章为帐务管理（日结/月结、财务对账、销账冲红）、掌上机抄表管理（任务下发、数据回传、异常上报）、银行划帐（托收文件生成/回盘处理）、系统报表（报表清单及口径）、系统管理（用户/角色/日志/参数）各补充二级功能分解和场景描述表。 | H10: 待确认
A11: Q-002 | B11: 3.2 系统总体功能-档案管理（对照4.1 档案基础数据） | C11: 信息缺失 | D11: 高 | E11: 管理客户立户档案，根据报装信息建立新客户档案，同时管理客户基本信息变更，如销户、过户、该表、缴费方式变更、银行信息变更等 | F11: 3.2档案管理描述了立户、销户、过户、缴费方式变更、银行信息变更及档案变更跟踪等核心业务，但第4章对应的4.1档案基础数据仅有用户状态/用户分类/抄表周期/行业分类/优惠类型5个码表功能，立户/销户/过户等业务功能全部缺失详述，也无变更审批流程、欠费用户能否销户等业务规则。 | G11: 在第4章新增「档案管理」功能组，为立户（报装信息来源与必录字段）、销户（欠费校验规则）、过户、换表、缴费方式变更、档案变更历史查询分别编写场景描述表，并附业务流程图说明审批环节与状态流转。 | H11: 待确认
A12: Q-003 | B12: 3.2 系统总体功能-抄表管理（对照4.7 抄表计划） | C12: 信息缺失 | D12: 高 | E12: 自动生成客户档期水费，同时提供水量异常减免、污水缓缴等功能 | F12: 3.2抄表管理承诺的水费自动生成、水量异常报表监控、水量异常减免、污水缓缴，在第4章4.7抄表计划（仅手工录入/表格录入/数据导入3项）中均无对应功能；同样，3.2收费管理提到的银行托收、代扣、增值税发票打印在第4章也无落点。算费规则（阶梯水价、污水费、违约金）作为营销系统核心完全未描述。 | G12: 补充「水费计算」场景表（计费公式、阶梯水价与优惠类型如何参与计算、污水费/垃圾费附加规则）、「水量异常审核与减免」场景表（异常判定阈值、减免审批权限）、「污水缓缴」场景表；或在3.2中删除本期不实现的承诺性描述。 | H12: 待确认
A13: Q-004 | B13: 3.2 系统总体功能-表务管理（对照4.6 水表基础数据） | C13: 信息缺失 | D13: 高 | E13: 管理水表日常操作如入库检验、表身号输录入库、出库、周期更换等信息记录 | F13: 3.2表务管理承诺水表全生命周期管理（入库检验、出库、周期更换、拆表、换表、故障、检定、周检及全程状态跟踪），但第4章唯一相关的4.6水表基础数据只有类型/口径/参数/厂家4个静态码表功能，全部生命周期业务功能均无详述。开发无法实现「从入库到处理及周期更换的全程状态信息及跟踪」，测试也无依据。 | G13: 在第4章新增「4.x 表务管理」小节，按场景表逐一描述：水表入库（含检验结果录入）、出库领用、装表/拆表/换表（含新旧表止度衔接规则）、水表检定与周检计划、水表状态机（在库-在装-待检-报废等状态及流转条件）。 | H13: 待确认
A14: Q-005 | B14: 4.2.3 表册顺序调整、4.7.2 表格录入、4.7.3 抄表数据导入-输入/输出 | C14: 信息缺失 | D14: 高 | E14: 无 | F14: 这三个功能的输入、输出栏均填「无」，与功能本身明显不符：表格录入的输入必然是Excel抄表文件，抄表数据导入的输入是抄表机数据文件，顺序调整的输入是户号与目标顺序号；导入类功能也必然有成功/失败结果输出。连文件格式（Excel模板列定义、抄表机数据文件格式）、字段校验规则、重复导入与异常数据（读数倒走、跳变超阈值）的处理、导入结果反馈都没有定义，按现文开发无法确定文件格式、字段和校验规则，测试无预期结果可比对，完全无从下手。 | G14: 按实际补全：4.7.2输入=「按模板格式的Excel抄表文件（户号、本期行至、抄表日期等列）」、4.7.3注明抄表机数据文件格式，两者均补充校验规则（户号存在性、本期行至≥上期、水量超阈值预警）、异常行处理方式（整批回滚或跳过并输出错误清单），输出=「导入成功N条/失败M条及失败原因清单」；4.2.3输入=「表册号、户号、目标顺序号」、输出=「调整后的表册抄表顺序列表」。 | H14: 待确认
A15: Q-006 | B15: 4.4.1 单户销账-输出 | C15: 信息缺失 | D15: 高 | E15: 展示用户欠费信息列表 | F15: 功能描述是「对选中的账单进行销账」，但输出只写了查询阶段的欠费列表，销账动作本身的结果（账单状态变为已缴、生成收费流水、打印票据、找零）完全未描述；部分缴费是否允许、滞纳金如何一并收取、重复销账如何拦截等业务规则和异常流缺失。全文24个场景表均无验收标准，补充说明几乎全为「无」，测试用例无法设计。 | G15: 重写输出为「销账成功后账单状态更新为已缴、生成收费流水号并支持打印票据；失败时提示原因」，补充业务规则（是否允许部分缴费、滞纳金处理、必须按账期顺序销账等）和异常分支；为每个场景表增加「验收标准」行，给出可度量的预期结果。 | H15: 待确认
A16: Q-007 | B16: 4.4.3 预收费-功能描述 | C16: 歧义 | D16: 高 | E16: 功能等同与单户销账，用户预存缴费，取款操作 | F16: 「功能等同与单户销账」（应为「等同于」）是模糊等价：预收费是预存款业务，与销账（核销欠费）业务规则本质不同，「等同」的范围（仅查询界面等同？还是收款流程等同？）无法确定；预存余额如何抵扣水费、「取款操作」的条件、审批和票据处理均未描述，核心业务规则完全缺失且涉及资金安全。 | G16: 删除「功能等同与单户销账」，独立描述预收费规则：预存金额录入方式、预存余额抵扣水费的时点与顺序（如出账时自动抵扣）、取款（退预存）的前提条件与审批流程、预收与退款的票据处理；如仅界面交互类似单户销账，明确写「查询界面交互同4.4.1」。 | H16: 待确认
A17: Q-008 | B17: 4.6.2 水表口径-功能描述（全文缺数据需求/数据字典） | C17: 信息缺失 | D17: 高 | E17: 可查询、编辑各个水表口径下的最大读数、换表读数、换表周期等信息 | F17: 全文没有数据需求或数据字典章节：用户档案、表册、账单、水表等核心实体的字段构成、类型、长度、必填性、取值范围均未定义，多处仅以「等信息」带过（如本条的「最大读数、换表读数、换表周期等」）。户号编码规则、金额精度、数据保存年限也未说明。数据库设计与界面字段只能靠开发自行猜测，验收时无对照依据。 | G17: 增加「数据需求」章节：给出核心实体（客户档案、表册、水表、抄表记录、账单、缴费流水、票据）的数据字典表（字段名、类型、长度、必填、取值/编码规则），并明确户号编码规则、金额单位与精度、历史数据保存年限。 | H17: 待确认
A18: Q-009 | B18: 4.6.4 水表厂家-输出 | C18: 模板残留 | D18: 高 | E18: 号码池内显示关联的隐号网关 | F18: 「号码池」「隐号网关」是通信/隐私号码类项目的术语，与水表厂家管理毫无关系，系模板残留；真正的输出内容「展示系统所有的水表水表厂家」被错放在补充说明栏且有「水表水表」重复错字。输出定义错误将直接导致开发实现和测试预期错误。 | G18: 输出改为「展示系统当前的水表厂家列表（含启用/禁用状态）」；删除「号码池内显示关联的隐号网关」；补充说明栏恢复为「无」或填写真实约束，并修正「水表水表」为「水表」。 | H18: 待确认
A19: Q-010 | B19: 5.2 对接第三方系统接口 | C19: 信息缺失 | D19: 高 | E19: 包括用户信息查询、、用户销账、销账冲红、对账等功能 | F19: 总述声明接口包含「销账冲红」，但5.2.1~5.2.3只定义了查询、销账、对账三个接口，冲红（冲正/退款）接口完全没有定义；银行代收场景中冲正是必备能力，缺失将导致联调时无法处理错缴退款。另外「查询、、用户销账」存在连续顿号笔误，「等功能」的「等」也使接口范围不封闭。 | G19: 补充「销账冲红」接口定义：请求地址、入参（bankentityno、原缴费流水号bankno、冲正金额、冲正日期等）、出参、幂等性与重复冲正的处理规则；删除多余顿号；将「等功能」改为封闭清单「共4个接口」。 | H19: 待确认
A20: Q-011 | B20: 5.2.2 缴费单销账-入参 | C20: 信息缺失 | D20: 高 | E20: 银行进账流水号，作为缴费、冲正、对账的凭证，不能重复 | F20: 接口仅约定bankno不能重复，但未定义银行重复提交同一bankno时的返回语义（幂等地返回原销账结果，还是返回特定错误码）；三个接口的出参均只给出code="1"、msg="ok"的成功示例，无错误码表（户号不存在、金额不符、重复销账、系统繁忙等）；也未约定超时后银行端的重试/冲正策略与接口鉴权签名机制。银行端程序无法进行异常分支开发和联调。 | G20: 在5.1或5.2增加接口公共约定小节：完整错误码表（code取值及含义）、幂等约定（相同bankno重复请求返回首次销账结果及原pychargeid）、超时时间与超时后的处理（先查询后重发或发起冲正）、签名算法与密钥分配、报文加密要求。 | H20: 待确认
... A50: Q-041 | B50: 5.2.2 缴费单销账-入参pyqbillid | C50: 错别字笔误 | D50: 低 | E50: 可以解决跨天滞纳金变化销账不成功、用户增加新欠费时销账不成功都棘手问题 | F50: 「都棘手问题」应为「等棘手问题」，接口字段描述是银行方开发的直接输入，病句影响外部单位阅读理解。 | G50: 改为「……用户增加新欠费时销账不成功等棘手问题」。 | H50: 待确认
